<robot name="test_robot">
  <link name="base_link">
    <visual>
      <geometry>
        <cylinder length="1.99999" radius="0.2"/>
      </geometry>
      <origin xyz="0.923955 0.3824995 0" rpy="0 1.5707 0.3925" />
    </visual>
  </link>

  <link name="link1">
    <visual>
      <geometry>
        <cylinder length="1" radius="0.1"/>
      </geometry>
         <material name="we">
        <color rgba="0 6 2 1"/>
      </material>
      <origin xyz="0.25023 0.43288 0" rpy="3.14 1.5707 1.04667"/>
    </visual>
  </link>

  <link name="link2">
    <visual>
      <geometry>
        <cylinder length="1" radius="0.05"/>
      </geometry>
      <origin xyz="0 0 0.5" rpy="0 0 0" />
        <material name="w">
        <color rgba="3 2 1 1"/>
      </material>
    </visual>
  </link>

  <link name="link3">
    <visual>
      <geometry>
        <sphere  radius="0.3"/>
      </geometry>
      <material name="white">
        <color rgba="1 1 1 1"/>
      </material>
    </visual>
  </link>

  <joint name="joint1" type="revolute">
    <parent link="base_link"/>
    <child link="link1"/>
    <origin xyz="1.84791 0.764999 0" rpy="0 0 0.3925" />
         <limit effort="1000.0" lower="-2.35619" upper="2.35619" velocity="0.5"/>
    <axis xyz="0 0 1" />
  </joint>

  <joint name="joint2" type="continuous">
    <parent link="link1"/>
    <child link="link2"/>
    <origin xyz="0.50046 0.86576 0" rpy="3.14 0 1.04667" />
    <axis xyz="0 0 1" />
  </joint>

  <joint name="joint3" type="continuous">
    <parent link="link2"/>
    <child link="link3"/>
    <origin xyz="0 0 1" rpy="0 1 0" />
    <axis xyz="0 0 1" />
  </joint>
</robot>
